Workbook

Sheet 2 блок
S1: 41.055
S2: 212.313
W4: 180.642
B7: ШИХТОВОЧНЫЙ ЛИСТ | M7: 419.934
A11: 59.823 | B11: Поставщики | C11: Стоимость, | D11: Состав шихты на МАЙ, % | F11: 16.422 | G11: % участия (ф. в.) | I11: 262.752 | J11: Остаток угля на открытом угольном складе, т | M11: 63.342 | N11: Расход в | O11: Запас угля, сут | P11: Влага (Wr), % | Q11: Зола (Ad), % | S11: 174.777 | U11: 52.785 | V11: Rо | W11: х, | X11: у, | Y11: сера | Z11: м.д. фосфора в золе, % | AB11: 182.988 | AK11: 170.085
A12: 60.996 | C12: 86.802 | D12: Утв. План | E12: факт (средн за период) | J12: 246.33 | K12: 2 блок | L12: ВСЕГО | M12: силосов, т | N12: сутки, т | U12: 3.519 | V12: % | W12: мм | X12: мм | Y12: % | AA12: 324.921 | AB12: зола | AC12: лет | AD12: Vt | AE12: Rо | AF12: Х,мм | AG12: У.мм | AH12: сера | AI12: фосфор | AJ12: фосфор | AK12: +6 мм | AL12: помол | AM12: пыль
F13: 17.595 | M13: =G13*$M$125/$G$125 -> 0 | N13: =SUM(M13:M14) -> 0 | O13: =IF(M13=0," ",L13/N13) | Q13: 9.2667 | S13: 39.0609 | U13: 96.186 | V13: 0.97359 | W13: 45.747 | X13: 24.633 | Y13: 0.56304 | AA13: 0.042228 | AB13: =($G13*Q13/$G$125) -> 0 | AC13: =($G13*S13/$G$125) -> 0 | AD13: =($G13*U13/$G$125) -> 0 | AE13: =($G13*V13/$G$125) -> 0 | AF13: =($G13*W13/$G$125) -> 0 | AG13: =($G13*X13/$G$125) -> 0 | AH13: =($G13*Y13/$G$125) -> 0 | AJ13: =($G13*AA13/$G$125) -> 0
F14: 17.595 | M14: =G14*$M$125/$G$125 -> 0 | AB14: =($G14*Q14/$G$125) -> 0 | AC14: =($G14*S14/$G$125) -> 0 | AD14: =($G14*U14/$G$125) -> 0 | AE14: =($G14*V14/$G$125) -> 0 | AF14: =($G14*W14/$G$125) -> 0 | AH14: =($G14*Y14/$G$125) -> 0 | AJ14: =($G14*AA14/$G$125) -> 0
B15: 184.161 | F15: 17.595 | H15: =G15*(100-P15)/100 -> 0 | I15: =H15/H$125*100 -> 0 | J15: 0 | K15: 0 | L15: =SUM(J15:K15) -> 0 | M15: =G15*$M$125/$G$125 -> 0 | N15: =SUM(M15:M17) -> 0 | O15: =IF(N15=0," ",(J15+#REF!)/N15) | P15: 15.9528 | Q15: 8.6802 | S15: 25.9233 | U15: 90.321 | V15: 1.06743 | W15: 53.958 | X15: 18.768 | Y15: 0.64515 | AA15: 0.042228 | AB15: =($G15*Q15/$G$125) -> 0 | AC15: =($G15*S15/$G$125) -> 0 | AD15: =($G15*U15/$G$125) -> 0 | AE15: =($G15*V15/$G$125) -> 0 | AF15: =($G15*W15/$G$125) -> 0 | AG15: =($G15*X15/$G$125) -> 0 | AH15: =($G15*Y15/$G$125) -> 0 | AJ15: =($G15*AA15/$G$125) -> 0 | AL15: 82.11 | AO15: 144.279
B16: 144.279 | F16: 17.595 | M16: =G16*$M$125/$G$125 -> 0 | O16: =IF(N16=0," ",(J16+#REF!)/N16) | Q16: 8.6802 | S16: 41.055 | U16: 99.705 | V16: 1.02051 | W16: 50.439 | X16: 24.633 | Y16: 0.48093 | AA16: 0.042228 | AB16: =($G16*Q16/$G$125) -> 0 | AC16: =($G16*S16/$G$125) -> 0 | AD16: =($G16*U16/$G$125) -> 0 | AE16: =($G16*V16/$G$125) -> 0 | AF16: =($G16*W16/$G$125) -> 0 | AG16: =($G16*X16/$G$125) -> 0 | AH16: =($G16*Y16/$G$125) -> 0 | AJ16: =($G16*AA16/$G$125) -> 0
B17: 144.279 | F17: 17.595 | M17: =G17*$M$125/$G$125 -> 0 | O17: =IF(N17=0," ",(J17+#REF!+K17)/N17) | Q17: 10.3224 | S17: 41.055 | U17: 90.321 | V17: 1.06743 | W17: 53.958 | X17: 18.768 | Y17: 0.64515 | AA17: 0.042228 | AB17: =($G17*Q17/$G$125) -> 0 | AC17: =($G17*S17/$G$125) -> 0 | AD17: =($G17*U17/$G$125) -> 0 | AE17: =($G17*V17/$G$125) -> 0 | AF17: =($G17*W17/$G$125) -> 0 | AG17: =($G17*X17/$G$125) -> 0 | AH17: =($G17*Y17/$G$125) -> 0 | AJ17: =($G17*AA17/$G$125) -> 0 | AO17: 144.279
B18: 231.081 | C18: 12915.199 | F18: 17.595 | J18: 0 | K18: 0 | L18: =SUM(J18:K18) -> 0 | M18: =G18*$M$125/$G$125 -> 0 | N18: =SUM(M18:M19) -> 0 | O18: =IF(N18=0," ",(J18+#REF!+K18)/N18) | Q18: 9.384 | S18: 41.2896 | U18: 99.705 | V18: 0.98532 | W18: 51.612 | X18: 23.46 | Y18: 0.4692 | AA18: 0.042228 | AB18: =($G18*Q18/$G$125) -> 0 | AC18: =($G18*S18/$G$125) -> 0 | AD18: =($G18*U18/$G$125) -> 0 | AE18: =($G18*V18/$G$125) -> 0 | AF18: =($G18*W18/$G$125) -> 0 | AG18: =($G18*X18/$G$125) -> 0 | AH18: =($G18*Y18/$G$125) -> 0 | AJ18: =($G18*AA18/$G$125) -> 0
A19: 232.254 | B19: Щедрухинская ГЖ (ш.Есаульская) | C19: 12915.199 | F19: 17.595 | M19: =G19*$M$125/$G$125 -> 0 | O19: =IF(N19=0," ",(J19+#REF!+K19)/N19) | Q19: 7.9764 | S19: 41.5242 | U19: 99.705 | V19: 0.98532 | W19: 51.612 | X19: 23.46 | Y19: 0.4692 | AA19: 0.042228 | AB19: =($G19*Q19/$G$125) -> 0 | AC19: =($G19*S19/$G$125) -> 0 | AD19: =($G19*U19/$G$125) -> 0 | AE19: =($G19*V19/$G$125) -> 0 | AF19: =($G19*W19/$G$125) -> 0 | AG19: =($G19*X19/$G$125) -> 0 | AH19: =($G19*Y19/$G$125) -> 0 | AJ19: =($G19*AA19/$G$125) -> 0
A20: 290.904 | B20: Распадская ГЖ | C20: 11436.386 | D20: 11.73 | E20: 11.183673 | F20: ГЖ | G20: 14.076 | J20: 2500 | K20: 3100 | L20: =SUM(J20:K20) -> 5600 | M20: =G20*M125/G125 -> 378.855 | N20: =SUM(M20:M21) -> 378.855 | O20: =IF(N20=0," ",(K20)/N20) -> 8.1825501 | Q20: 8.9148 | S20: 41.2896 | U20: 102.051 | V20: 1.06743 | W20: 39.882 | X20: 29.325 | Y20: 0.83283 | Z20: 0.804678 | AA20: 0.0619344 | AB20: =($G20*Q20/$G$125) -> 0.912 | AC20: =($G20*S20/$G$125) -> 4.224 | AD20: =($G20*U20/$G$125) -> 10.44 | AE20: =($G20*V20/$G$125) -> 0.1092 | AF20: =($G20*W20/$G$125) -> 4.08 | AG20: =($G20*X20/$G$125) -> 3 | AH20: =($G20*Y20/$G$125) -> 0.0852 | AI20: =($G20*Z20/$G$125) -> 0.08232 | AJ20: =($G20*AA20/$G$125) -> 0.006336 | AK20: 7.7418 | AL20: 82.11 | AO20: 152.49
A21: 232.254 | B21: Распадская ГЖ | C21: 11436.386 | F21: 17.595 | L21: =SUM(J21:K21) -> 0 | M21: =$M$125*G21/G125 -> 0 | O21: =IF(N21=0," ",(K21)/N21) | Q21: 8.5629 | S21: 41.4069 | U21: 102.051 | V21: 1.06743 | W21: 39.882 | X21: 29.325 | Y21: 0.83283 | Z21: 0.804678 | AA21: 0.0619344 | AB21: =($G21*Q21/$G$125) -> 0 | AC21: =($G21*S21/$G$125) -> 0 | AD21: =($G21*U21/$G$125) -> 0 | AE21: =($G21*V21/$G$125) -> 0 | AF21: =($G21*W21/$G$125) -> 0 | AG21: =($G21*X21/$G$125) -> 0 | AH21: =($G21*Y21/$G$125) -> 0 | AI21: =($G21*Z21/$G$125) -> 0 | AJ21: =($G21*AA21/$G$125) -> 0 | AO21: 152.49
B22: 112.608 | C22: 9532.5605 | F22: 37.536 | H22: =G22*(100-P22)/100 -> 0 | I22: =H22/H$125*100 -> 0 | K22: 0 | L22: =SUM(J22:K22) -> 0 | M22: =$M$125*G22/G125 -> 0 | N22: =SUM(M22:M24) -> 0 | O22: =IF(N22=0," ",(K22)/N22) | P22: 11.73 | Q22: 10.6743 | S22: 37.1841 | U22: 104.397 | V22: 0.96186 | W22: 38.709 | X22: 31.671 | Y22: 0.49266 | AA22: 0.032844 | AB22: =($G22*Q22/$G$125) -> 0 | AC22: =($G22*S22/$G$125) -> 0 | AD22: =($G22*U22/$G$125) -> 0 | AE22: =($G22*V22/$G$125) -> 0 | AF22: =($G22*W22/$G$125) -> 0 | AG22: =($G22*X22/$G$125) -> 0 | AH22: =($G22*Y22/$G$125) -> 0 | AI22: =($G22*Z22/$G$125) -> 0 | AJ22: =($G22*AA22/$G$125) -> 0 | AK22: 3.1671 | AL22: 103.5759 | AO22: 72.726 | AV22: 116.127 | AW22: 39.0609 | AX22: 118.473 | AZ22: 9.5013 | BA22: 40.4685 | BB22: 105.57
A23: 12 шт | B23: Кузнецкая ГЖ+Ж | C23: 9532.5605 | F23: 37.536 | L23: =SUM(J23:K23) -> 0 | M23: =G23*M125/G125 -> 0 | O23: =IF(N23=0," ",(K23)/N23) | Q23: 9.7359 | S23: 38.5917 | U23: 104.397 | V23: 0.96186 | W23: 38.709 | X23: 31.671 | Y23: 0.52785 | AA23: 0.032844 | AB23: =($G23*Q23/$G$125) -> 0 | AC23: =($G23*S23/$G$125) -> 0 | AD23: =($G23*U23/$G$125) -> 0 | AE23: =($G23*V23/$G$125) -> 0 | AF23: =($G23*W23/$G$125) -> 0 | AG23: =($G23*X23/$G$125) -> 0 | AH23: =($G23*Y23/$G$125) -> 0 | AI23: =($G23*Z23/$G$125) -> 0 | AJ23: =($G23*AA23/$G$125) -> 0 | AO23: 5.865
B24: 112.608 | C24: 9532.5605 | F24: 37.536 | L24: =SUM(J24:K24) -> 0 | M24: =G24*M125/G125 -> 0 | O24: =IF(N24=0," ",(K24)/N24) | U24: 102.051 | V24: 1.0557 | AB24: =($G24*Q24/$G$125) -> 0 | AC24: =($G24*S24/$G$125) -> 0 | AD24: =($G24*U24/$G$125) -> 0 | AE24: =($G24*V24/$G$125) -> 0 | AF24: =($G24*W24/$G$125) -> 0 | AG24: =($G24*X24/$G$125) -> 0 | AH24: =($G24*Y24/$G$125) -> 0 | AI24: =($G24*Z24/$G$125) -> 0 | AJ24: =($G24*AA24/$G$125) -> 0 | AO24: 5.865
A25: 124.338 | B25: Уголь + добавки | F25: 37.536 | K25: 19600 | L25: =SUM(J25:K25) -> 19600 | M25: =G25*M125/G125 -> 0 | O25: =IF(N25=0," ",(K25)/N25) | Q25: 9.8532 | S25: 36.363 | U25: 99.705 | V25: 1.02051 | W25: 17.595 | X25: 36.363 | Y25: 0.5865 | AB25: =($G25*Q25/$G$125) -> 0 | AC25: =($G25*S25/$G$125) -> 0 | AD25: =($G25*U25/$G$125) -> 0 | AE25: =($G25*V25/$G$125) -> 0 | AF25: =($G25*W25/$G$125) -> 0 | AG25: =($G25*X25/$G$125) -> 0 | AH25: =($G25*Y25/$G$125) -> 0 | AI25: =($G25*Z25/$G$125) -> 0 | AJ25: =($G25*AA25/$G$125) -> 0 | AO25: 147.798
B26: 100.878 | F26: 37.536 | L26: =SUM(J26:K26) -> 0 | M26: =G26*$M$125/$G$125 -> 0 | N26: =SUM(M26:M27) -> 0 | O26: =IF(N26=0," ",(K26)/N26) | Q26: 7.8591 | S26: 40.4685 | U26: 103.224 | V26: 0.98532 | W26: 51.612 | X26: 28.152 | Y26: 0.49266 | AA26: 0.032844 | AB26: =($G26*Q26/$G$125) -> 0 | AC26: =($G26*S26/$G$125) -> 0 | AD26: =($G26*U26/$G$125) -> 0 | AE26: =($G26*V26/$G$125) -> 0 | AF26: =($G26*W26/$G$125) -> 0 | AG26: =($G26*X26/$G$125) -> 0 | AH26: =($G26*Y26/$G$125) -> 0 | AI26: =($G26*Z26/$G$125) -> 0 | AJ26: =($G26*AA26/$G$125) -> 0 | AL26: 82.11 | AO26: 100.878
F27: 37.536 | L27: =SUM(J27:K27) -> 0 | M27: =G27*$M$125/$G$125 -> 0 | O27: =IF(N27=0," ",(K27)/N27) | AB27: =($G27*Q27/$G$125) -> 0 | AC27: =($G27*S27/$G$125) -> 0 | AD27: =($G27*U27/$G$125) -> 0 | AE27: =($G27*V27/$G$125) -> 0 | AF27: =($G27*W27/$G$125) -> 0 | AG27: =($G27*X27/$G$125) -> 0 | AH27: =($G27*Y27/$G$125) -> 0 | AI27: =($G27*Z27/$G$125) -> 0 | AJ27: =($G27*AA27/$G$125) -> 0
B28: 186.507 | F28: 37.536 | L28: =SUM(J28:K28) -> 0 | M28: =G28*$M$125/$G$125 -> 0 | N28: =SUM(M28:M29) -> 0 | O28: =IF(N28=0," ",(K28)/N28) | Q28: 8.3283 | S28: 39.6474 | U28: 100.878 | V28: 1.00878 | W28: 38.709 | X28: 32.844 | Y28: 0.71553 | AA28: 0.032844 | AB28: =($G28*Q28/$G$125) -> 0 | AC28: =($G28*S28/$G$125) -> 0 | AD28: =($G28*U28/$G$125) -> 0 | AE28: =($G28*V28/$G$125) -> 0 | AF28: =($G28*W28/$G$125) -> 0 | AG28: =($G28*X28/$G$125) -> 0 | AH28: =($G28*Y28/$G$125) -> 0 | AI28: =($G28*Z28/$G$125) -> 0 | AJ28: =($G28*AA28/$G$125) -> 0 | AL28: 82.11 | AO28: 186.507
F29: 37.536 | L29: =SUM(J29:K29) -> 0 | M29: =G29*$M$125/$G$125 -> 0 | O29: =IF(N29=0," ",(K29)/N29) | AB29: =($G29*Q29/$G$125) -> 0 | AC29: =($G29*S29/$G$125) -> 0 | AD29: =($G29*U29/$G$125) -> 0 | AE29: =($G29*V29/$G$125) -> 0 | AF29: =($G29*W29/$G$125) -> 0 | AG29: =($G29*X29/$G$125) -> 0 | AH29: =($G29*Y29/$G$125) -> 0 | AI29: =($G29*Z29/$G$125) -> 0 | AJ29: =($G29*AA29/$G$125) -> 0
B30: 125.511 | F30: 4.692 | L30: =SUM(J30:K30) -> 0 | M30: =$M$125*G30/$G$125 -> 0 | N30: =SUM(M30:M31) -> 0 | O30: =IF(N30=0," ",(K30)/N30) | Q30: 10.3224 | S30: 41.1723 | U30: 104.397 | V30: 1.02051 | X30: 32.844 | Y30: 0.8211 | AB30: =($G30*Q30/$G$125) -> 0 | AC30: =($G30*S30/$G$125) -> 0 | AD30: =($G30*U30/$G$125) -> 0 | AE30: =($G30*V30/$G$125) -> 0 | AF30: =($G30*W30/$G$125) -> 0 | AG30: =($G30*X30/$G$125) -> 0 | AH30: =($G30*Y30/$G$125) -> 0 | AI30: =($G30*Z30/$G$125) -> 0 | AJ30: =($G30*AA30/$G$125) -> 0 | AO30: 125.511
B31: 125.511 | F31: 4.692 | L31: =SUM(J31:K31) -> 0 | M31: =$M$125*G31/$G$125 -> 0 | O31: =IF(N31=0," ",(K31)/N31) | Q31: 10.3224 | S31: 41.1723 | U31: 104.397 | V31: 1.02051 | X31: 32.844 | Y31: 0.83283 | AB31: =($G31*Q31/$G$125) -> 0 | AC31: =($G31*S31/$G$125) -> 0 | AD31: =($G31*U31/$G$125) -> 0 | AE31: =($G31*V31/$G$125) -> 0 | AF31: =($G31*W31/$G$125) -> 0 | AG31: =($G31*X31/$G$125) -> 0 | AH31: =($G31*Y31/$G$125) -> 0 | AI31: =($G31*Z31/$G$125) -> 0 | AJ31: =($G31*AA31/$G$125) -> 0 | AO31: 125.511
B32: 294.423 | C32: 15261.199 | E32: 0 | F32: Ж | J32: 0 | K32: 0 | L32: =SUM(J32:K32) -> 0 | M32: =$M$125*G32/G125 -> 0 | N32: =SUM(M32:M34) -> 0 | O32: =IF(N32=0," ",(K32)/N32) | Q32: 8.4456 | S32: 37.4187 | U32: 110.262 | V32: 1.12608 | W32: 16.422 | X32: 37.536 | Y32: 0.62169 | AA32: 0.0499698 | AB32: =($G32*Q32/$G$125) -> 0 | AC32: =($G32*S32/$G$125) -> 0 | AD32: =($G32*U32/$G$125) -> 0 | AE32: =($G32*V32/$G$125) -> 0 | AF32: =($G32*W32/$G$125) -> 0 | AG32: =($G32*X32/$G$125) -> 0 | AH32: =($G32*Y32/$G$125) -> 0 | AI32: =($G32*Z32/$G$125) -> 0 | AJ32: =($G32*AA32/$G$125) -> 0 | AL32: 60.0576 | AO32: 201.756
B33: 226.389 | F33: 4.692 | M33: =$M$125*G33/G125 -> 0 | O33: =IF(N33=0," ",(K33)/N33) | Q33: 9.9705 | S33: 35.8938 | U33: 97.359 | V33: 1.10262 | W33: 43.401 | X33: 34.017 | Y33: 0.62169 | AA33: 0.0499698 | AB33: =($G33*Q33/$G$125) -> 0 | AC33: =($G33*S33/$G$125) -> 0 | AD33: =($G33*U33/$G$125) -> 0 | AE33: =($G33*V33/$G$125) -> 0 | AF33: =($G33*W33/$G$125) -> 0 | AG33: =($G33*X33/$G$125) -> 0 | AH33: =($G33*Y33/$G$125) -> 0 | AI33: =($G33*Z33/$G$125) -> 0 | AJ33: =($G33*AA33/$G$125) -> 0
A34: 265.098 | B34: Кузнецкая (ш. Ерунаковская 8) Ж | F34: 4.692 | M34: =$M$125*G34/G125 -> 0 | O34: =IF(N34=0," ",(K34)/N34) | Q34: 8.211 | S34: 36.8322 | U34: 97.359 | V34: 1.10262 | W34: 15.249 | X34: 36.363 | Y34: 0.60996 | AA34: 0.0499698 | AB34: =($G34*Q34/$G$125) -> 0 | AC34: =($G34*S34/$G$125) -> 0 | AD34: =($G34*U34/$G$125) -> 0 | AE34: =($G34*V34/$G$125) -> 0 | AF34: =($G34*W34/$G$125) -> 0 | AG34: =($G34*X34/$G$125) -> 0 | AH34: =($G34*Y34/$G$125) -> 0 | AI34: =($G34*Z34/$G$125) -> 0 | AJ34: =($G34*AA34/$G$125) -> 0 | AK34: 9.384 | AL34: 68.1513 | AO34: 195.891
A35: 263.925 | B35: Щедрухинская Ж (ш.Юбилейная) | C35: 16434.199 | F35: 4.692 | H35: =G35*(100-P35)/100 -> 0 | I35: =H35/H$125*100 -> 0 | L35: =SUM(J35:K35) -> 0 | M35: =$M$125*G35/G125 -> 0 | N35: =SUM(M35:M38) -> 0 | O35: =IF(N35=0," ",(K35)/N35) | P35: 11.73 | Q35: 9.5013 | S35: 37.0668 | U35: 95.013 | V35: 1.13781 | W35: 24.633 | X35: 38.709 | Y35: 0.63342 | AA35: 0.0550137 | AB35: =($G35*Q35/$G$125) -> 0 | AC35: =($G35*S35/$G$125) -> 0 | AD35: =($G35*U35/$G$125) -> 0 | AE35: =($G35*V35/$G$125) -> 0 | AF35: =($G35*W35/$G$125) -> 0 | AG35: =($G35*X35/$G$125) -> 0 | AH35: =($G35*Y35/$G$125) -> 0 | AI35: =($G35*Z35/$G$125) -> 0 | AJ35: =($G35*AA35/$G$125) -> 0 | AO35: 73.899
B36: 253.368 | C36: 17607.199 | F36: 4.692 | L36: =SUM(J36:K36) -> 0 | M36: =$M$125*G36/G125 -> 0 | O36: =IF(N36=0," ",(K36)/N36) | Q36: 10.2051 | S36: 37.536 | U36: 93.84 | V36: 1.12608 | W36: 25.806 | X36: 38.709 | Y36: 0.64515 | AA36: 0.0550137 | AB36: =($G36*Q36/$G$125) -> 0 | AC36: =($G36*S36/$G$125) -> 0 | AD36: =($G36*U36/$G$125) -> 0 | AE36: =($G36*V36/$G$125) -> 0 | AF36: =($G36*W36/$G$125) -> 0 | AG36: =($G36*X36/$G$125) -> 0 | AH36: =($G36*Y36/$G$125) -> 0 | AI36: =($G36*Z36/$G$125) -> 0 | AJ36: =($G36*AA36/$G$125) -> 0 | AO36: 194.718
B37: 253.368 | C37: 17607.199 | F37: 4.692 | L37: =SUM(J37:K37) -> 0 | M37: =$M$125*G37/G125 -> 0 | O37: =IF(N37=0," ",(K37)/N37) | Q37: 9.9705 | S37: 37.3014 | U37: 97.359 | V37: 1.13781 | W37: 25.806 | X37: 38.709 | Y37: 0.64515 | AA37: 0.0550137 | AB37: =($G37*Q37/$G$125) -> 0 | AC37: =($G37*S37/$G$125) -> 0 | AD37: =($G37*U37/$G$125) -> 0 | AE37: =($G37*V37/$G$125) -> 0 | AF37: =($G37*W37/$G$125) -> 0 | AG37: =($G37*X37/$G$125) -> 0 | AH37: =($G37*Y37/$G$125) -> 0 | AI37: =($G37*Z37/$G$125) -> 0 | AJ37: =($G37*AA37/$G$125) -> 0
A38: 263.925 | B38: Щедрухинская Ж (ш.Юбилейная) | C38: 17607.199 | F38: 4.692 | L38: =SUM(J38:K38) -> 0 | M38: =$M$125*G38/$G$125 -> 0 | O38: =IF(N38=0," ",(K38)/N38) | Q38: 9.384 | S38: 37.0668 | U38: 95.013 | V38: 1.13781 | W38: 24.633 | X38: 38.709 | Y38: 0.63342 | AA38: 0.0550137 | AB38: =($G38*Q38/$G$125) -> 0 | AC38: =($G38*S38/$G$125) -> 0 | AD38: =($G38*U38/$G$125) -> 0 | AE38: =($G38*V38/$G$125) -> 0 | AF38: =($G38*W38/$G$125) -> 0 | AG38: =($G38*X38/$G$125) -> 0 | AH38: =($G38*Y38/$G$125) -> 0 | AI38: =($G38*Z38/$G$125) -> 0 | AJ38: =($G38*AA38/$G$125) -> 0 | AK38: 14.1933 | AL38: 87.1539 | AO38: 194.718
A39: 356.592 | B39: Кузнецкая (ш. Юбилейная) | C39: 14368.886 | D39: 22.287 | E39: 19.530612 | F39: Ж | G39: 11.73 | K39: 3000 | L39: =SUM(J39:K39) -> 3000 | M39: =$M$125*G39/$G$125 -> 315.7125 | N39: =SUM(M39:M43) -> 599.85375 | O39: =IF(N39=0," ",(K39)/N39) -> 5.0012191 | Q39: 10.0878 | S39: 37.4187 | U39: 97.359 | V39: 1.13781 | W39: 19.941 | X39: 37.536 | Y39: 0.76245 | Z39: 0.647496 | AA39: 0.0550137 | AB39: =($G39*Q39/$G$125) -> 0.86 | AC39: =($G39*S39/$G$125) -> 3.19 | AD39: =($G39*U39/$G$125) -> 8.3 | AE39: =($G39*V39/$G$125) -> 0.097 | AF39: =($G39*W39/$G$125) -> 1.7 | AG39: =($G39*X39/$G$125) -> 3.2 | AH39: =($G39*Y39/$G$125) -> 0.065 | AI39: =($G39*Z39/$G$125) -> 0.0552 | AJ39: =($G39*AA39/$G$125) -> 0.00469 | AL39: 71.9049 | AO39: 121.992
A40: 9 с/с (11 шт) | B40: Кузнецкая (ш. Юбилейная) | C40: 14368.886 | F40: 4.692 | G40: 10.557 | M40: =$M$125*G40/$G$125 -> 284.14125 | O40: =IF(N40=0," ",(K40)/N40) | Q40: 9.8532 | S40: 37.8879 | U40: 97.359 | V40: 1.13781 | W40: 19.941 | X40: 37.536 | Y40: 0.76245 | Z40: 0.764796 | AA40: 0.0550137 | AB40: =($G40*Q40/$G$125) -> 0.756 | AC40: =($G40*S40/$G$125) -> 2.907 | AD40: =($G40*U40/$G$125) -> 7.47 | AE40: =($G40*V40/$G$125) -> 0.0873 | AF40: =($G40*W40/$G$125) -> 1.53 | AG40: =($G40*X40/$G$125) -> 2.88 | AH40: =($G40*Y40/$G$125) -> 0.0585 | AI40: =($G40*Z40/$G$125) -> 0.05868 | AJ40: =($G40*AA40/$G$125) -> 0.004221
A41: 362.457 | B41: Кузнецкая (ш. Юбилейная) | C41: 14368.886 | F41: 4.692 | L41: =SUM(J41:K41) -> 0 | M41: =$M$125*G41/$G$125 -> 0 | O41: =IF(N41=0," ",(K41)/N41) | Q41: 10.2051 | S41: 38.0052 | U41: 97.359 | V41: 1.13781 | W41: 19.941 | X41: 37.536 | Y41: 0.76245 | Z41: 0.647496 | AA41: 0.0550137 | AB41: =($G41*Q41/$G$125) -> 0 | AC41: =($G41*S41/$G$125) -> 0 | AD41: =($G41*U41/$G$125) -> 0 | AE41: =($G41*V41/$G$125) -> 0 | AF41: =($G41*W41/$G$125) -> 0 | AG41: =($G41*X41/$G$125) -> 0 | AH41: =($G41*Y41/$G$125) -> 0 | AI41: =($G41*Z41/$G$125) -> 0 | AJ41: =($G41*AA41/$G$125) -> 0
A42: 265.098 | B42: Кузнецкая (ш. Юбилейная) | C42: 14368.886 | F42: 4.692 | L42: =SUM(J42:K42) -> 0 | M42: =$M$125*G42/$G$125 -> 0 | O42: =IF(N42=0," ",(K42)/N42) | Q42: 10.9089 | S42: 36.5976 | U42: 99.705 | V42: 1.10262 | W42: 17.595 | X42: 39.882 | Y42: 0.62169 | Z42: 0.647496 | AA42: 0.0550137 | AB42: =($G42*Q42/$G$125) -> 0 | AC42: =($G42*S42/$G$125) -> 0 | AD42: =($G42*U42/$G$125) -> 0 | AE42: =($G42*V42/$G$125) -> 0 | AF42: =($G42*W42/$G$125) -> 0 | AG42: =($G42*X42/$G$125) -> 0 | AH42: =($G42*Y42/$G$125) -> 0 | AI42: =($G42*Z42/$G$125) -> 0 | AJ42: =($G42*AA42/$G$125) -> 0
B43: 121.992 | C43: 14368.886 | F43: 4.692 | L43: =SUM(J43:K43) -> 0 | M43: =$M$125*G43/$G$125 -> 0 | O43: =IF(N43=0," ",(K43)/N43) | Q43: 10.3224 | S43: 36.2457 | U43: 99.705 | V43: 1.07916 | W43: 37.536 | X43: 24.633 | Y43: 0.68034 | Z43: 0.647496 | AA43: 0.0369495 | AB43: =($G43*Q43/$G$125) -> 0 | AC43: =($G43*S43/$G$125) -> 0 | AD43: =($G43*U43/$G$125) -> 0 | AE43: =($G43*V43/$G$125) -> 0 | AF43: =($G43*W43/$G$125) -> 0 | AG43: =($G43*X43/$G$125) -> 0 | AH43: =($G43*Y43/$G$125) -> 0 | AI43: =($G43*Z43/$G$125) -> 0 | AJ43: =($G43*AA43/$G$125) -> 0 | AO43: 121.992
B44: 259.233 | C44: 14368.886 | E44: 0 | F44: Ж | J44: 0 | K44: 0 | L44: =SUM(J44:K44) -> 0 | M44: =G44*$M$125/$G$125 -> 0 | N44: =SUM(M44:M46) -> 0 | O44: =IF(N44=0," ",(K44)/N44) | Q44: 10.0878 | S44: 37.6533 | U44: 98.532 | V44: 1.09089 | W44: 31.671 | X44: 36.363 | Y44: 0.69207 | Z44: 0.647496 | AA44: 0.0550137 | AB44: =($G44*Q44/$G$125) -> 0 | AC44: =($G44*S44/$G$125) -> 0 | AD44: =($G44*U44/$G$125) -> 0 | AE44: =($G44*V44/$G$125) -> 0 | AF44: =($G44*W44/$G$125) -> 0 | AG44: =($G44*X44/$G$125) -> 0 | AH44: =($G44*Y44/$G$125) -> 0 | AI44: =($G44*Z44/$G$125) -> 0 | AJ44: =($G44*AA44/$G$125) -> 0 | AK44: 29.325 | AO44: 119.646
B45: 259.233 | C45: 14368.886 | F45: 4.692 | L45: =SUM(J45:K45) -> 0 | M45: =G45*$M$125/$G$125 -> 0 | O45: =IF(N45=0," ",(K45)/N45) | Q45: 10.4397 | S45: 37.1841 | U45: 98.532 | V45: 1.09089 | W45: 31.671 | X45: 36.363 | Y45: 0.69207 | Z45: 0.647496 | AA45: 0.0550137 | AB45: =($G45*Q45/$G$125) -> 0 | AC45: =($G45*S45/$G$125) -> 0 | AD45: =($G45*U45/$G$125) -> 0 | AE45: =($G45*V45/$G$125) -> 0 | AF45: =($G45*W45/$G$125) -> 0 | AG45: =($G45*X45/$G$125) -> 0 | AH45: =($G45*Y45/$G$125) -> 0 | AI45: =($G45*Z45/$G$125) -> 0 | AJ45: =($G45*AA45/$G$125) -> 0 | AO45: 119.646
B46: 259.233 | C46: 14368.886 | F46: 4.692 | M46: =G46*$M$125/$G$125 -> 0 | O46: =IF(N46=0," ",(K46)/N46) | Q46: 10.0878 | S46: 37.6533 | U46: 98.532 | V46: 1.09089 | W46: 31.671 | X46: 36.363 | Y46: 0.69207 | Z46: 0.647496 | AA46: 0.0550137 | AB46: =($G46*Q46/$G$125) -> 0 | AC46: =($G46*S46/$G$125) -> 0 | AD46: =($G46*U46/$G$125) -> 0 | AE46: =($G46*V46/$G$125) -> 0 | AF46: =($G46*W46/$G$125) -> 0 | AG46: =($G46*X46/$G$125) -> 0 | AH46: =($G46*Y46/$G$125) -> 0 | AI46: =($G46*Z46/$G$125) -> 0 | AJ46: =($G46*AA46/$G$125) -> 0
...

Sheet 3 блок
E1: ШИХТОВОЧНЫЙ ЛИСТ | J1: ='2 блок'!M7 -> на 25.05.26 - 26.05.26
B2: 3 блок
A4: 208.794 | B4: Поставщики | C4: Стоимость, | D4: Состав шихты на АПРЕЛЬ, % | F4: 16.422 | G4: Участ. | H4: Остаток | I4: Расход из | J4: Расход в | K4: Запас | L4: Зола, | M4: Летучие (Vd), % | O4: 52.785 | P4: Rо | Q4: х, | R4: У, | S4: сера | T4: м.д. фосфора в золе, % | U4: фосфор | V4: расчет показателей качества | AE4: 202.929
C5: 86.802 | D5: Утв. План | E5: факт (средн за период) | G5: 3.519 | H5: на складе,т | I5: силосов, т | J5: сутки, т | K5: угля, сут | L5: % | M5: 1 смена | N5: 2 смена | O5: % | P5: % | Q5: мм | R5: мм | S5: % | V5: 10.557 | W5: лет | X5: Ив | Y5: Vt | Z5: Rо | AA5: х, мм | AB5: У.мм | AC5: сера
B6: 231.081 | C6: 16630.911 | F6: 17.595 | H6: 0 | I6: =G6*I$171/$G$171 -> 0 | J6: =SUM(I6:I8) -> 0 | K6: =IF(J6=0," ",H6/J6) | L6: 9.5013 | M6: 41.055 | O6: 96.186 | P6: 0.97359 | Q6: 49.266 | R6: 24.633 | S6: 0.4692 | U6: 0.042228 | V6: =(G6*L6/$G$171) -> 0 | W6: =(G6*M6/$G$171) -> 0 | X6: =(#REF!*N6/$G$171) -> #REF! | Y6: =G6*O6/100 -> 0 | Z6: =(G6*P6/100) -> 0 | AA6: =(G6*Q6/$G$171) -> 0 | AB6: =(G6*R6/$G$171) -> 0 | AC6: =(G6*S6/$G$171) -> 0 | AE6: =(G6*U6/$G$171) -> 0
B7: 229.908 | C7: 16630.911 | F7: 17.595 | I7: =G7*I$171/$G$171 -> 0 | L7: 7.5072 | M7: 41.4069 | O7: 102.051 | P7: 0.98532 | Q7: 52.785 | R7: 25.806 | S7: 0.4692 | U7: 0.042228 | V7: =(G7*L7/$G$171) -> 0 | W7: =(G7*M7/$G$171) -> 0 | X7: =(#REF!*N7/$G$171) -> #REF! | Y7: =G7*O7/100 -> 0 | Z7: =(G7*P7/100) -> 0 | AA7: =(G7*Q7/$G$171) -> 0 | AB7: =(G7*R7/$G$171) -> 0 | AC7: =(G7*S7/$G$171) -> 0 | AE7: =(G7*U7/$G$171) -> 0
B8: 231.081 | C8: 16630.911 | F8: 17.595 | I8: =G8*I$171/$G$171 -> 0 | L8: 10.4397 | M8: 41.055 | O8: 96.186 | P8: 0.97359 | Q8: 49.266 | R8: 24.633 | S8: 0.4692 | U8: 0.042228 | V8: =(G8*L8/$G$171) -> 0 | W8: =(G8*M8/$G$171) -> 0 | X8: =(#REF!*N8/$G$171) -> #REF! | Y8: =G8*O8/100 -> 0 | Z8: =(G8*P8/100) -> 0 | AA8: =(G8*Q8/$G$171) -> 0 | AB8: =(G8*R8/$G$171) -> 0 | AC8: =(G8*S8/$G$171) -> 0 | AE8: =(G8*U8/$G$171) -> 0
B9: 184.161 | C9: 12915.199 | F9: 17.595 | H9: 0 | I9: =G9*I$171/$G$171 -> 0 | J9: =SUM(I9:I16) -> 0 | K9: =IF(J9=0," ",H9/J9) | L9: 6.4515 | M9: 41.2896 | O9: 98.532 | P9: 1.02051 | Q9: 49.266 | R9: 24.633 | S9: 0.48093 | U9: 0.042228 | V9: =(G9*L9/$G$171) -> 0 | W9: =(G9*M9/$G$171) -> 0 | X9: =(#REF!*N9/$G$171) -> #REF! | Y9: =G9*O9/100 -> 0 | Z9: =(G9*P9/100) -> 0 | AA9: =(G9*Q9/$G$171) -> 0 | AB9: =(G9*R9/$G$171) -> 0 | AC9: =(G9*S9/$G$171) -> 0 | AE9: =(G9*U9/$G$171) -> 0
B10: 184.161 | F10: 17.595 | I10: =G10*I$171/$G$171 -> 0 | L10: 9.8532 | M10: 41.9934 | O10: 97.359 | P10: 1.04397 | Q10: 45.747 | R10: 23.46 | S10: 0.45747 | U10: 0.042228 | V10: =(G10*L10/$G$171) -> 0 | W10: =(G10*M10/$G$171) -> 0 | X10: =(#REF!*N10/$G$171) -> #REF! | Y10: =G10*O10/100 -> 0 | Z10: =(G10*P10/100) -> 0 | AA10: =(G10*Q10/$G$171) -> 0 | AB10: =(G10*R10/$G$171) -> 0 | AC10: =(G10*S10/$G$171) -> 0 | AE10: =(G10*U10/$G$171) -> 0
B11: 184.161 | F11: 17.595 | I11: =G11*I$171/$G$171 -> 0 | L11: 7.2726 | M11: 41.7588 | O11: 97.359 | P11: 1.03224 | Q11: 51.612 | R11: 24.633 | S11: 0.51612 | U11: 0.042228 | V11: =(G11*L11/$G$171) -> 0 | W11: =(G11*M11/$G$171) -> 0 | X11: =(#REF!*N11/$G$171) -> #REF! | Y11: =G11*O11/100 -> 0 | Z11: =(G11*P11/100) -> 0 | AA11: =(G11*Q11/$G$171) -> 0 | AB11: =(G11*R11/$G$171) -> 0 | AC11: =(G11*S11/$G$171) -> 0 | AE11: =(G11*U11/$G$171) -> 0
B12: 184.161 | F12: 17.595 | I12: =G12*I$171/$G$171 -> 0 | L12: 10.557 | M12: 40.4685 | O12: 97.359 | P12: 1.04397 | Q12: 43.401 | R12: 24.633 | S12: 0.4692 | U12: 0.042228 | V12: =(G12*L12/$G$171) -> 0 | W12: =(G12*M12/$G$171) -> 0 | X12: =(#REF!*N12/$G$171) -> #REF! | Y12: =G12*O12/100 -> 0 | Z12: =(G12*P12/100) -> 0 | AA12: =(G12*Q12/$G$171) -> 0 | AB12: =(G12*R12/$G$171) -> 0 | AC12: =(G12*S12/$G$171) -> 0 | AE12: =(G12*U12/$G$171) -> 0
B13: 184.161 | F13: 17.595 | I13: =G13*I$171/$G$171 -> 0 | L13: 6.8034 | M13: 40.7031 | O13: 97.359 | P13: 1.04397 | Q13: 48.093 | R13: 24.633 | S13: 0.45747 | U13: 0.042228 | V13: =(G13*L13/$G$171) -> 0 | W13: =(G13*M13/$G$171) -> 0 | X13: =(#REF!*N13/$G$171) -> #REF! | Y13: =G13*O13/100 -> 0 | Z13: =(G13*P13/100) -> 0 | AA13: =(G13*Q13/$G$171) -> 0 | AB13: =(G13*R13/$G$171) -> 0 | AC13: =(G13*S13/$G$171) -> 0 | AE13: =(G13*U13/$G$171) -> 0
B14: 184.161 | F14: 17.595 | I14: =G14*I$171/$G$171 -> 0 | L14: 8.3283 | M14: 40.8204 | O14: 97.359 | P14: 1.04397 | Q14: 48.093 | R14: 25.806 | S14: 0.49266 | U14: 0.042228 | V14: =(G14*L14/$G$171) -> 0 | W14: =(G14*M14/$G$171) -> 0 | X14: =(#REF!*N14/$G$171) -> #REF! | Y14: =G14*O14/100 -> 0 | Z14: =(G14*P14/100) -> 0 | AA14: =(G14*Q14/$G$171) -> 0 | AB14: =(G14*R14/$G$171) -> 0 | AC14: =(G14*S14/$G$171) -> 0 | AE14: =(G14*U14/$G$171) -> 0
B15: 184.161 | F15: 17.595 | I15: =G15*I$171/$G$171 -> 0 | L15: 6.4515 | M15: 41.8761 | O15: 99.705 | P15: 1.0557 | Q15: 59.823 | R15: 22.287 | S15: 0.48093 | U15: 0.042228 | V15: =(G15*L15/$G$171) -> 0 | W15: =(G15*M15/$G$171) -> 0 | X15: =(#REF!*N15/$G$171) -> #REF! | Y15: =G15*O15/100 -> 0 | Z15: =(G15*P15/100) -> 0 | AA15: =(G15*Q15/$G$171) -> 0 | AB15: =(G15*R15/$G$171) -> 0 | AC15: =(G15*S15/$G$171) -> 0 | AE15: =(G15*U15/$G$171) -> 0
B16: 184.161 | F16: 17.595 | I16: =G16*I$171/$G$171 -> 0 | L16: 6.4515 | M16: 41.33652 | O16: 98.532 | P16: 1.02051 | Q16: 49.266 | R16: 24.633 | S16: 0.48093 | U16: 0.042228 | V16: =(G16*L16/$G$171) -> 0 | W16: =(G16*M16/$G$171) -> 0 | X16: =(#REF!*N16/$G$171) -> #REF! | Y16: =G16*O16/100 -> 0 | Z16: =(G16*P16/100) -> 0 | AA16: =(G16*Q16/$G$171) -> 0 | AB16: =(G16*R16/$G$171) -> 0 | AC16: =(G16*S16/$G$171) -> 0 | AE16: =(G16*U16/$G$171) -> 0
B17: 231.081 | C17: 12915.199 | F17: 17.595 | H17: 0 | I17: =G17*I$171/$G$171 -> 0 | J17: =SUM(I17:I20) -> 0 | K17: =IF(J17=0," ",H17/J17) | L17: 9.2667 | M17: 40.1166 | O17: 99.705 | P17: 0.98532 | Q17: 51.612 | R17: 23.46 | S17: 0.48093 | U17: 0.042228 | V17: =(G17*L17/$G$171) -> 0 | W17: =(G17*M17/$G$171) -> 0 | X17: =(#REF!*N17/$G$171) -> #REF! | Y17: =G17*O17/100 -> 0 | Z17: =(G17*P17/100) -> 0 | AA17: =(G17*Q17/$G$171) -> 0 | AB17: =(G17*R17/$G$171) -> 0 | AC17: =(G17*S17/$G$171) -> 0 | AE17: =(G17*U17/$G$171) -> 0
B18: 231.081 | C18: 12915.199 | F18: 17.595 | I18: =G18*I$171/$G$171 -> 0 | L18: 8.7975 | M18: 42.228 | O18: 99.705 | P18: 0.98532 | Q18: 51.612 | R18: 23.46 | S18: 0.44574 | U18: 0.42228 | V18: =(G18*L18/$G$171) -> 0 | W18: =(G18*M18/$G$171) -> 0 | X18: =(#REF!*N18/$G$171) -> #REF! | Y18: =G18*O18/100 -> 0 | Z18: =(G18*P18/100) -> 0 | AA18: =(G18*Q18/$G$171) -> 0 | AB18: =(G18*R18/$G$171) -> 0 | AC18: =(G18*S18/$G$171) -> 0 | AE18: =(G18*U18/$G$171) -> 0
B19: 231.081 | C19: 12915.199 | F19: 17.595 | I19: =G19*I$171/$G$171 -> 0 | L19: 9.2667 | M19: 40.3512 | O19: 99.705 | P19: 0.98532 | Q19: 51.612 | R19: 23.46 | S19: 0.44574 | U19: 0.42228 | V19: =(G19*L19/$G$171) -> 0 | W19: =(G19*M19/$G$171) -> 0 | X19: =(#REF!*N19/$G$171) -> #REF! | Y19: =G19*O19/100 -> 0 | Z19: =(G19*P19/100) -> 0 | AA19: =(G19*Q19/$G$171) -> 0 | AB19: =(G19*R19/$G$171) -> 0 | AC19: =(G19*S19/$G$171) -> 0 | AE19: =(G19*U19/$G$171) -> 0
B20: 146.625 | F20: 17.595 | I20: =G20*I$171/$G$171 -> 0 | U20: 0.042228 | V20: =(G20*L20/$G$171) -> 0 | W20: =(G20*M20/$G$171) -> 0 | X20: =(#REF!*N20/$G$171) -> #REF! | Y20: =G20*O20/100 -> 0 | Z20: =(G20*P20/100) -> 0 | AA20: =(G20*Q20/$G$171) -> 0 | AB20: =(G20*R20/$G$171) -> 0 | AC20: =(G20*S20/$G$171) -> 0 | AE20: =(G20*U20/$G$171) -> 0
A21: 8.211 | B21: Распадская ГЖ | C21: 11436.386 | D21: 42.228 | E21: 38.530612 | F21: ГЖ | G21: 17.595 | H21: 7800 | I21: =G21*I$171/$G$171 -> 339.38861 | J21: =SUM(I21:I27) -> 927.6622 | K21: =IF(J21=0," ",H21/J21) -> 8.4082331 | L21: 7.6245 | M21: 41.5242 | O21: 102.051 | P21: 1.06743 | Q21: 46.92 | R21: 28.152 | S21: 0.85629 | T21: 0.804678 | U21: 0.0619344 | V21: =(G21*L21/$G$171) -> 0.975 | W21: =(G21*M21/$G$171) -> 5.31 | X21: =(#REF!*N21/$G$171) -> #REF! | Y21: =G21*O21/100 -> 13.05 | Z21: =(G21*P21/100) -> 0.1365 | AA21: =(G21*Q21/$G$171) -> 6 | AB21: =(G21*R21/$G$171) -> 3.6 | AC21: =(G21*S21/$G$171) -> 0.1095 | AD21: =(G21*T21/$G$171) -> 0.1029 | AE21: =(G21*U21/$G$171) -> 0.00792
A22: 10.557 | B22: Распадская ГЖ | C22: 11436.386 | F22: 17.595 | G22: 15.249 | I22: =G22*I$171/$G$171 -> 294.1368 | L22: 8.3283 | M22: 41.1723 | O22: 102.051 | P22: 1.06743 | Q22: 36.363 | R22: 26.979 | S22: 0.83283 | T22: 0.804678 | U22: 0.0619344 | V22: =(G22*L22/$G$171) -> 0.923 | W22: =(G22*M22/$G$171) -> 4.563 | X22: =(#REF!*N22/$G$171) -> #REF! | Y22: =G22*O22/100 -> 11.31 | Z22: =(G22*P22/100) -> 0.1183 | AA22: =(G22*Q22/$G$171) -> 4.03 | AB22: =(G22*R22/$G$171) -> 2.99 | AC22: =(G22*S22/$G$171) -> 0.0923 | AD22: =(G22*T22/$G$171) -> 0.08918 | AE22: =(G22*U22/$G$171) -> 0.006864
B23: 97.359 | C23: 11436.386 | F23: 17.595 | I23: =G23*I$171/$G$171 -> 0 | L23: 9.0321 | M23: 41.9934 | O23: 102.051 | P23: 1.06743 | Q23: 35.19 | R23: 29.325 | S23: 0.75072 | T23: 0.804678 | U23: 0.0619344 | V23: =(G23*L23/$G$171) -> 0 | W23: =(G23*M23/$G$171) -> 0 | X23: =(#REF!*N23/$G$171) -> #REF! | Y23: =G23*O23/100 -> 0 | Z23: =(G23*P23/100) -> 0 | AA23: =(G23*Q23/$G$171) -> 0 | AB23: =(G23*R23/$G$171) -> 0 | AC23: =(G23*S23/$G$171) -> 0 | AD23: =(G23*T23/$G$171) -> 0 | AE23: =(G23*U23/$G$171) -> 0
A24: 17.595 | B24: Распадская ГЖ | C24: 11436.386 | F24: 17.595 | G24: 15.249 | I24: =G24*I$171/$G$171 -> 294.1368 | L24: 7.6245 | M24: 41.8761 | O24: 102.051 | P24: 1.06743 | Q24: 46.92 | R24: 28.152 | S24: 0.85629 | T24: 0.804678 | U24: 0.0619344 | V24: =(G24*L24/$G$171) -> 0.845 | W24: =(G24*M24/$G$171) -> 4.641 | X24: =(#REF!*N24/$G$171) -> #REF! | Y24: =G24*O24/100 -> 11.31 | Z24: =(G24*P24/100) -> 0.1183 | AA24: =(G24*Q24/$G$171) -> 5.2 | AB24: =(G24*R24/$G$171) -> 3.12 | AC24: =(G24*S24/$G$171) -> 0.0949 | AD24: =(G24*T24/$G$171) -> 0.08918 | AE24: =(G24*U24/$G$171) -> 0.006864
A25: 18.768 | B25: Распадская ГЖ | C25: 11436.386 | F25: 17.595 | I25: =G25*I$171/$G$171 -> 0 | L25: 7.9764 | M25: 41.5242 | O25: 102.051 | P25: 1.06743 | Q25: 38.709 | R25: 29.325 | S25: 0.77418 | T25: 0.804678 | U25: 0.0619344 | V25: =(G25*L25/$G$171) -> 0 | W25: =(G25*M25/$G$171) -> 0 | X25: =(#REF!*N25/$G$171) -> #REF! | Y25: =G25*O25/100 -> 0 | Z25: =(G25*P25/100) -> 0 | AA25: =(G25*Q25/$G$171) -> 0 | AB25: =(G25*R25/$G$171) -> 0 | AC25: =(G25*S25/$G$171) -> 0 | AD25: =(G25*T25/$G$171) -> 0 | AE25: =(G25*U25/$G$171) -> 0
A26: 23.46 | B26: Распадская ГЖ | C26: 11436.386 | F26: 17.595 | I26: =G26*I$171/$G$171 -> 0 | L26: 8.0937 | M26: 41.9934 | O26: 102.051 | P26: 1.06743 | Q26: 35.19 | R26: 28.152 | S26: 0.79764 | T26: 0.804678 | V26: =(G26*L26/$G$171) -> 0 | W26: =(G26*M26/$G$171) -> 0 | X26: =(#REF!*N26/$G$171) -> #REF! | Y26: =G26*O26/100 -> 0 | Z26: =(G26*P26/100) -> 0 | AA26: =(G26*Q26/$G$171) -> 0 | AB26: =(G26*R26/$G$171) -> 0 | AC26: =(G26*S26/$G$171) -> 0 | AD26: =(G26*T26/$G$171) -> 0 | AE26: =(G26*U26/$G$171) -> 0
B27: 97.359 | C27: 9763.8643 | F27: 17.595 | I27: =G27*I$171/$G$171 -> 0 | L27: 7.5072 | M27: 41.7588 | O27: 99.705 | P27: 0.9384 | Q27: 38.709 | R27: 28.152 | S27: 0.80937 | T27: 0.731952 | U27: 0.0619344 | V27: =(G27*L27/$G$171) -> 0 | W27: =(G27*M27/$G$171) -> 0 | X27: =(#REF!*N27/$G$171) -> #REF! | Y27: =G27*O27/100 -> 0 | Z27: =(G27*P27/100) -> 0 | AA27: =(G27*Q27/$G$171) -> 0 | AB27: =(G27*R27/$G$171) -> 0 | AC27: =(G27*S27/$G$171) -> 0 | AD27: =(G27*T27/$G$171) -> 0 | AE27: =(G27*U27/$G$171) -> 0
B28: 112.608 | F28: 50.439 | I28: =G28*I$171/$G$171 -> 0 | J28: =+SUM(I28:I34) -> 0 | K28: =IF(J28=0," ",H28/J28) | L28: 9.5013 | M28: 35.3073 | O28: 104.397 | P28: 0.96186 | Q28: 26.979 | R28: 31.671 | S28: 0.5865 | U28: 0.032844 | V28: =(G28*L28/$G$171) -> 0 | W28: =(G28*M28/$G$171) -> 0 | X28: =(#REF!*N28/$G$171) -> #REF! | Y28: =G28*O28/100 -> 0 | Z28: =(G28*P28/100) -> 0 | AA28: =(G28*Q28/$G$171) -> 0 | AB28: =(G28*R28/$G$171) -> 0 | AC28: =(G28*S28/$G$171) -> 0 | AD28: =(G28*T28/$G$171) -> 0 | AE28: =(G28*U28/$G$171) -> 0
B29: 112.608 | F29: 50.439 | I29: =G29*I$171/$G$171 -> 0 | L29: 8.5629 | M29: 36.0111 | O29: 96.186 | P29: 1.07916 | Q29: 68.034 | R29: 28.152 | S29: 0.49266 | U29: 0.032844 | V29: =(G29*L29/$G$171) -> 0 | W29: =(G29*M29/$G$171) -> 0 | X29: =(#REF!*N29/$G$171) -> #REF! | Y29: =G29*O29/100 -> 0 | Z29: =(G29*P29/100) -> 0 | AA29: =(G29*Q29/$G$171) -> 0 | AB29: =(G29*R29/$G$171) -> 0 | AC29: =(G29*S29/$G$171) -> 0 | AD29: =(G29*T29/$G$171) -> 0 | AE29: =(G29*U29/$G$171) -> 0
B30: 72.726 | F30: 50.439 | I30: =G30*I$171/$G$171 -> 0 | L30: 9.0321 | M30: 37.536 | O30: 99.705 | P30: 1.02051 | Q30: 37.536 | R30: 29.325 | S30: 0.56304 | V30: =(G30*L30/$G$171) -> 0 | W30: =(G30*M30/$G$171) -> 0 | X30: =(#REF!*N30/$G$171) -> #REF! | Y30: =G30*O30/100 -> 0 | Z30: =(G30*P30/100) -> 0 | AA30: =(G30*Q30/$G$171) -> 0 | AB30: =(G30*R30/$G$171) -> 0 | AC30: =(G30*S30/$G$171) -> 0 | AD30: =(G30*T30/$G$171) -> 0 | AE30: =(G30*U30/$G$171) -> 0
B31: 5.865 | F31: 50.439 | I31: =G31*I$171/$G$171 -> 0 | L31: 9.0321 | M31: 38.1225 | O31: 99.705 | P31: 1.02051 | Q31: 36.363 | R31: 31.671 | S31: 0.59823 | V31: =(G31*L31/$G$171) -> 0 | W31: =(G31*M31/$G$171) -> 0 | X31: =(#REF!*N31/$G$171) -> #REF! | Y31: =G31*O31/100 -> 0 | Z31: =(G31*P31/100) -> 0 | AA31: =(G31*Q31/$G$171) -> 0 | AB31: =(G31*R31/$G$171) -> 0 | AC31: =(G31*S31/$G$171) -> 0 | AD31: =(G31*T31/$G$171) -> 0 | AE31: =(G31*U31/$G$171) -> 0
B32: 5.865 | F32: 50.439 | I32: =G32*I$171/$G$171 -> 0 | L32: 8.6802 | O32: 99.705 | P32: 1.02051 | Q32: 42.228 | R32: 29.325 | S32: 0.5865 | V32: =(G32*L32/$G$171) -> 0 | W32: =(G32*M32/$G$171) -> 0 | X32: =(#REF!*N32/$G$171) -> #REF! | Y32: =G32*O32/100 -> 0 | Z32: =(G32*P32/100) -> 0 | AA32: =(G32*Q32/$G$171) -> 0 | AB32: =(G32*R32/$G$171) -> 0 | AC32: =(G32*S32/$G$171) -> 0 | AD32: =(G32*T32/$G$171) -> 0 | AE32: =(G32*U32/$G$171) -> 0
B33: 5.865 | F33: 50.439 | I33: =G33*I$171/$G$171 -> 0 | L33: 9.384 | M33: 36.9495 | O33: 99.705 | P33: 1.02051 | Q33: 23.46 | R33: 29.325 | S33: 0.63342 | V33: =(G33*L33/$G$171) -> 0 | W33: =(G33*M33/$G$171) -> 0 | X33: =(#REF!*N33/$G$171) -> #REF! | Y33: =G33*O33/100 -> 0 | Z33: =(G33*P33/100) -> 0 | AA33: =(G33*Q33/$G$171) -> 0 | AB33: =(G33*R33/$G$171) -> 0 | AC33: =(G33*S33/$G$171) -> 0 | AD33: =(G33*T33/$G$171) -> 0 | AE33: =(G33*U33/$G$171) -> 0
B34: 5.865 | F34: 50.439 | I34: =G34*I$171/$G$171 -> 0 | L34: 7.3899 | O34: 102.051 | P34: 1.0557 | R34: 32.844 | S34: 0.55131 | V34: =(G34*L34/$G$171) -> 0 | W34: =(G34*M34/$G$171) -> 0 | X34: =(#REF!*N34/$G$171) -> #REF! | Y34: =G34*O34/100 -> 0 | Z34: =(G34*P34/100) -> 0 | AA34: =(G34*Q34/$G$171) -> 0 | AB34: =(G34*R34/$G$171) -> 0 | AC34: =(G34*S34/$G$171) -> 0 | AD34: =(G34*T34/$G$171) -> 0 | AE34: =(G34*U34/$G$171) -> 0
B35: 100.878 | F35: 50.439 | I35: =G35*I$171/$G$171 -> 0 | J35: =SUM(I35:I36) -> 0 | K35: =IF(J35=0," ",H35/J35) | L35: 9.8532 | M35: 37.536 | O35: 103.224 | P35: 0.98532 | Q35: 51.612 | R35: 28.152 | S35: 0.49266 | U35: 0.032844 | V35: =(G35*L35/$G$171) -> 0 | W35: =(G35*M35/$G$171) -> 0 | X35: =(#REF!*N35/$G$171) -> #REF! | Y35: =G35*O35/100 -> 0 | Z35: =(G35*P35/100) -> 0 | AA35: =(G35*Q35/$G$171) -> 0 | AB35: =(G35*R35/$G$171) -> 0 | AC35: =(G35*S35/$G$171) -> 0 | AD35: =(G35*T35/$G$171) -> 0 | AE35: =(G35*U35/$G$171) -> 0
B36: 161.874 | F36: 50.439 | I36: =G36*I$171/$G$171 -> 0 | L36: 9.5013 | O36: 99.705 | P36: 1.02051 | Q36: 48.093 | R36: 37.536 | S36: 0.51612 | V36: =(G36*L36/$G$171) -> 0 | W36: =(G36*M36/$G$171) -> 0 | X36: =(#REF!*N36/$G$171) -> #REF! | Y36: =G36*O36/100 -> 0 | Z36: =(G36*P36/100) -> 0 | AA36: =(G36*Q36/$G$171) -> 0 | AB36: =(G36*R36/$G$171) -> 0 | AC36: =(G36*S36/$G$171) -> 0 | AD36: =(G36*T36/$G$171) -> 0 | AE36: =(G36*U36/$G$171) -> 0
B37: 186.507 | F37: 50.439 | I37: =G37*I$171/$G$171 -> 0 | J37: =SUM(I37:I38) -> 0 | K37: =IF(J37=0," ",H37/J37) | V37: =(G37*L37/$G$171) -> 0 | W37: =(G37*M37/$G$171) -> 0 | X37: =(#REF!*N37/$G$171) -> #REF! | Y37: =G37*O37/100 -> 0 | Z37: =(G37*P37/100) -> 0 | AA37: =(G37*Q37/$G$171) -> 0 | AB37: =(G37*R37/$G$171) -> 0 | AC37: =(G37*S37/$G$171) -> 0 | AD37: =(G37*T37/$G$171) -> 0 | AE37: =(G37*U37/$G$171) -> 0
B38: 186.507 | F38: 50.439 | I38: =G38*I$171/$G$171 -> 0 | V38: =(G38*L38/$G$171) -> 0 | W38: =(G38*M38/$G$171) -> 0 | X38: =(#REF!*N38/$G$171) -> #REF! | Y38: =G38*O38/100 -> 0 | Z38: =(G38*P38/100) -> 0 | AA38: =(G38*Q38/$G$171) -> 0 | AB38: =(G38*R38/$G$171) -> 0 | AC38: =(G38*S38/$G$171) -> 0 | AD38: =(G38*T38/$G$171) -> 0 | AE38: =(G38*U38/$G$171) -> 0
A39: 16.422 | B39: Кузнецкая Ж (ш. Юбилейная) | C39: 16434.199 | F39: 4.692 | H39: 0 | I39: =G39*I$171/$G$171 -> 0 | J39: =SUM(I39:I43) -> 0 | K39: =IF(J39=0," ",H39/J39) | L39: 9.2667 | M39: 37.0668 | O39: 98.532 | P39: 1.09089 | Q39: 16.422 | R39: 39.882 | S39: 0.52785 | U39: 0.0499698 | V39: =(G39*L39/$G$171) -> 0 | W39: =(G39*M39/$G$171) -> 0 | X39: =(#REF!*N39/$G$171) -> #REF! | Y39: =G39*O39/100 -> 0 | Z39: =(G39*P39/100) -> 0 | AA39: =(G39*Q39/$G$171) -> 0 | AB39: =(G39*R39/$G$171) -> 0 | AC39: =(G39*S39/$G$171) -> 0 | AD39: =(G39*T39/$G$171) -> 0 | AE39: =(G39*U39/$G$171) -> 0
B40: 200.583 | C40: 15261.199 | F40: 4.692 | I40: =G40*I$171/$G$171 -> 0 | L40: 8.211 | M40: 36.9495 | O40: 98.532 | P40: 1.09089 | Q40: 16.422 | R40: 39.882 | S40: 0.52785 | U40: 0.0499698 | V40: =(G40*L40/$G$171) -> 0 | W40: =(G40*M40/$G$171) -> 0 | X40: =(#REF!*N40/$G$171) -> #REF! | Y40: =G40*O40/100 -> 0 | Z40: =(G40*P40/100) -> 0 | AA40: =(G40*Q40/$G$171) -> 0 | AB40: =(G40*R40/$G$171) -> 0 | AC40: =(G40*S40/$G$171) -> 0 | AD40: =(G40*T40/$G$171) -> 0 | AE40: =(G40*U40/$G$171) -> 0
B41: 200.583 | C41: 15261.199 | F41: 4.692 | I41: =G41*I$171/$G$171 -> 0 | L41: 7.9764 | M41: 36.7149 | O41: 98.532 | P41: 1.09089 | Q41: 16.422 | R41: 39.882 | S41: 0.52785 | U41: 0.0499698 | V41: =(G41*L41/$G$171) -> 0 | W41: =(G41*M41/$G$171) -> 0 | X41: =(#REF!*N41/$G$171) -> #REF! | Y41: =G41*O41/100 -> 0 | Z41: =(G41*P41/100) -> 0 | AA41: =(G41*Q41/$G$171) -> 0 | AB41: =(G41*R41/$G$171) -> 0 | AC41: =(G41*S41/$G$171) -> 0 | AD41: =(G41*T41/$G$171) -> 0 | AE41: =(G41*U41/$G$171) -> 0
...

Sheet Отклонения от БЮДЖЕТА и ПЛАНА
A3: 385.917
A4: 36.363
A5: 23.46 | B5: Стоимость в январе, руб./т | C5: 2 блок | J5: 62.169 | Q5: 221.697
G6: 225.216 | N6: 225.216 | U6: 225.216
C7: 354.246 | D7: План PRM | E7: Утв. План | F7: факт | G7: Б2025 | H7: План PRM | I7: =E7 -> Утв. План | J7: Б2026 | K7: План PRM | L7: =E7 -> Утв. План | M7: факт | N7: Б2025 | O7: План PRM | P7: =E7 -> Утв. План | Q7: Б2025 | R7: План PRM | S7: =E7 -> Утв. План | T7: факт | U7: Б2025 | V7: План PRM | W7: =E7 -> Утв. План
A8: 234.6 | G8: =+F8-C8 -> 0 | I8: =F8-E8 -> 0 | N8: =+M8-J8 -> 0 | P8: =M8-L8 -> 0 | Q8: =C8*$B$60+J8*$B$61 -> 0 | S8: =E8*$B$60+L8*$B$61 -> 0 | T8: =F8*$B$60+M8*$B$61 -> 0 | U8: =+T8-Q8 -> 0 | V8: =+T8-R8 -> 0 | W8: =T8-S8 -> 0
A9: Абашевская / Кузнецкая ГЖ (ш.Есаульская) | E9: 0 | G9: =+F9-C9 -> 0 | I9: =F9-E9 -> 0 | L9: 0 | N9: =+M9-J9 -> 0 | P9: =M9-L9 -> 0 | Q9: =C9*$B$60+J9*$B$61 -> 0 | S9: =E9*$B$60+L9*$B$61 -> 0 | T9: =F9*$B$60+M9*$B$61 -> 0 | U9: =+T9-Q9 -> 0 | V9: =+T9-R9 -> 0 | W9: =T9-S9 -> 0
A10: Распадская ГЖ | B10: 9763.8643 | C10: 14.05254 | E10: ='2 блок'!D20 -> 10 | F10: ='2 блок'!E20 -> 11.183673 | G10: =+F10-C10 -> -0.79632653 | I10: =F10-E10 -> 1.1836735 | J10: 36.30435 | L10: ='3 блок'!D21 -> 36 | M10: ='3 блок'!E21 -> 38.530612 | N10: =+M10-J10 -> 7.5806122 | P10: =M10-L10 -> 2.5306122 | Q10: =C10*$B$60+J10*$B$61 -> 21.398605 | S10: =E10*$B$60+L10*$B$61 -> 22.909 | T10: =F10*$B$60+M10*$B$61 -> 24.761429 | U10: =+T10-Q10 -> 3.3628236 | V10: =+T10-R10 -> 24.761429 | W10: =T10-S10 -> 1.8524286
A11: Кузнецкая ГЖ+Ж | B11: 16279.598 | G11: =+F11-C11 -> 0 | I11: =F11-E11 -> 0 | N11: =+M11-J11 -> 0 | P11: =M11-L11 -> 0 | Q11: =C11*$B$60+J11*$B$61 -> 0 | S11: =E11*$B$60+L11*$B$61 -> 0 | T11: =F11*$B$60+M11*$B$61 -> 0 | U11: =+T11-Q11 -> 0 | V11: =+T11-R11 -> 0 | W11: =T11-S11 -> 0
A12: Абашевская ГЖ+Ж | B12: 16763.46 | G12: =+F12-C12 -> 0 | I12: =F12-E12 -> 0 | N12: =+M12-J12 -> 0 | P12: =M12-L12 -> 0 | Q12: =C12*$B$60+J12*$B$61 -> 0 | S12: =E12*$B$60+L12*$B$61 -> 0 | T12: =F12*$B$60+M12*$B$61 -> 0 | U12: =+T12-Q12 -> 0 | V12: =+T12-R12 -> 0 | W12: =T12-S12 -> 0
A13: Распадская ГЖ+Ж | B13: 16763.46 | G13: =+F13-C13 -> 0 | I13: =F13-E13 -> 0 | N13: =+M13-J13 -> 0 | P13: =M13-L13 -> 0 | Q13: =C13*$B$60+J13*$B$61 -> 0 | S13: =E13*$B$60+L13*$B$61 -> 0 | T13: =F13*$B$60+M13*$B$61 -> 0 | U13: =+T13-Q13 -> 0 | V13: =+T13-R13 -> 0 | W13: =T13-S13 -> 0
A14: 215.832 | G14: =+F14-C14 -> 0 | I14: =F14-E14 -> 0 | N14: =+M14-J14 -> 0 | P14: =M14-L14 -> 0 | Q14: =C14*$B$60+J14*$B$61 -> 0 | U14: =+T14-Q14 -> 0 | V14: =+T14-R14 -> 0 | W14: =T14-S14 -> 0
A15: 214.659 | G15: =+F15-C15 -> 0 | I15: =F15-E15 -> 0 | N15: =+M15-J15 -> 0 | P15: =M15-L15 -> 0 | Q15: =C15*$B$60+J15*$B$61 -> 0 | U15: =+T15-Q15 -> 0 | V15: =+T15-R15 -> 0 | W15: =T15-S15 -> 0
A16: 227.562 | E16: 0 | G16: =+F16-C16 -> 0 | I16: =F16-E16 -> 0 | L16: 0 | N16: =+M16-J16 -> 0 | P16: =M16-L16 -> 0 | Q16: =C16*$B$60+J16*$B$61 -> 0 | S16: =E16*$B$60+L16*$B$61 -> 0 | T16: =F16*$B$60+M16*$B$61 -> 0 | U16: =+T16-Q16 -> 0 | V16: =+T16-R16 -> 0 | W16: =T16-S16 -> 0
A17: 307.326 | B17: 14261.803 | C17: =16.89+0.25 -> 17.14 | E17: ='2 блок'!D39+'2 блок'!D44+'2 блок'!D47 -> 19 | F17: ='2 блок'!E39+'2 блок'!E44+'2 блок'!E47 -> 19.530612 | G17: =+F17-C17 -> 2.3906122 | I17: =F17-E17 -> 0.53061224 | J17: =7.48+0.08 -> 7.56 | L17: ='3 блок'!D51+'3 блок'!D55+'3 блок'!D48 -> 3 | M17: ='3 блок'!E48+'3 блок'!E51+'3 блок'!E55 -> 0.81632653 | N17: =+M17-J17 -> -6.7436735 | P17: =M17-L17 -> -2.1836735 | Q17: =C17*$B$60+J17*$B$61 -> 12.38353 | S17: =E17*$B$60+L17*$B$61 -> 11.056 | T17: =F17*$B$60+M17*$B$61 -> 10.238969 | U17: =+T17-Q17 -> -2.1445606 | V17: =+T17-R17 -> 10.238969 | W17: =T17-S17 -> -0.81703061
B18: 13945.844 | G18: =+F18-C18 -> 0 | I18: =F18-E18 -> 0 | N18: =+M18-J18 -> 0 | P18: =M18-L18 -> 0 | Q18: =C18*$B$60+J18*$B$61 -> 0 | S18: =E18*$B$60+L18*$B$61 -> 0 | T18: =F18*$B$60+M18*$B$61 -> 0 | U18: =+T18-Q18 -> 0 | V18: =+T18-R18 -> 0 | W18: =T18-S18 -> 0
B19: 16311.738 | G19: =+F19-C19 -> 0 | I19: =F19-E19 -> 0 | N19: =+M19-J19 -> 0 | P19: =M19-L19 -> 0 | Q19: =C19*$B$60+J19*$B$61 -> 0 | S19: =E19*$B$60+L19*$B$61 -> 0 | T19: =F19*$B$60+M19*$B$61 -> 0 | U19: =+T19-Q19 -> 0 | V19: =+T19-R19 -> 0 | W19: =T19-S19 -> 0
A20: 194.718 | B20: 16311.738 | G20: =+F20-C20 -> 0 | I20: =F20-E20 -> 0 | N20: =+M20-J20 -> 0 | P20: =M20-L20 -> 0 | Q20: =C20*$B$60+J20*$B$61 -> 0 | U20: =+T20-Q20 -> 0 | V20: =+T20-R20 -> 0 | W20: =T20-S20 -> 0
A21: 121.992 | B21: 13088.803 | E21: 0 | G21: =+F21-C21 -> 0 | I21: =F21-E21 -> 0 | L21: 0 | N21: =+M21-J21 -> 0 | P21: =M21-L21 -> 0 | Q21: =C21*$B$60+J21*$B$61 -> 0 | S21: =E21*$B$60+L21*$B$61 -> 0 | T21: =F21*$B$60+M21*$B$61 -> 0 | U21: =+T21-Q21 -> 0 | V21: =+T21-R21 -> 0 | W21: =T21-S21 -> 0
A22: 119.646 | B22: 16196.033 | G22: =+F22-C22 -> 0 | I22: =F22-E22 -> 0 | N22: =+M22-J22 -> 0 | P22: =M22-L22 -> 0 | Q22: =C22*$B$60+J22*$B$61 -> 0 | S22: =E22*$B$60+L22*$B$61 -> 0 | T22: =F22*$B$60+M22*$B$61 -> 0 | U22: =+T22-Q22 -> 0 | V22: =+T22-R22 -> 0 | W22: =T22-S22 -> 0
A23: 285.039 | E23: 0 | G23: =+F23-C23 -> 0 | I23: =F23-E23 -> 0 | L23: ='3 блок'!D76 -> 0 | N23: =+M23-J23 -> 0 | P23: =M23-L23 -> 0 | Q23: =C23*$B$60+J23*$B$61 -> 0 | S23: =E23*$B$60+L23*$B$61 -> 0 | T23: =F23*$B$60+M23*$B$61 -> 0 | U23: =+T23-Q23 -> 0 | V23: =+T23-R23 -> 0 | W23: =T23-S23 -> 0
A24: 224.043 | G24: =+F24-C24 -> 0 | I24: =F24-E24 -> 0 | N24: =+M24-J24 -> 0 | P24: =M24-L24 -> 0 | Q24: =C24*$B$60+J24*$B$61 -> 0 | S24: =E24*$B$60+L24*$B$61 -> 0 | T24: =F24*$B$60+M24*$B$61 -> 0 | U24: =+T24-Q24 -> 0 | V24: =+T24-R24 -> 0 | W24: =T24-S24 -> 0
A25: 217.005 | G25: =+F25-C25 -> 0 | I25: =F25-E25 -> 0 | N25: =+M25-J25 -> 0 | P25: =M25-L25 -> 0 | Q25: =C25*$B$60+J25*$B$61 -> 0 | S25: =E25*$B$60+L25*$B$61 -> 0 | T25: =F25*$B$60+M25*$B$61 -> 0 | U25: =+T25-Q25 -> 0 | V25: =+T25-R25 -> 0 | W25: =T25-S25 -> 0
A26: 218.178 | G26: =+F26-C26 -> 0 | I26: =F26-E26 -> 0 | N26: =+M26-J26 -> 0 | P26: =M26-L26 -> 0 | Q26: =C26*$B$60+J26*$B$61 -> 0 | S26: =E26*$B$60+L26*$B$61 -> 0 | T26: =F26*$B$60+M26*$B$61 -> 0 | U26: =+T26-Q26 -> 0 | V26: =+T26-R26 -> 0 | W26: =T26-S26 -> 0
A27: 337.824 | B27: 13632.066 | E27: ='2 блок'!D58 -> 0 | G27: =+F27-C27 -> 0 | I27: =F27-E27 -> 0 | N27: =+M27-J27 -> 0 | P27: =M27-L27 -> 0 | Q27: =C27*$B$60+J27*$B$61 -> 0 | S27: =E27*$B$60+L27*$B$61 -> 0 | T27: =F27*$B$60+M27*$B$61 -> 0 | U27: =+T27-Q27 -> 0 | V27: =+T27-R27 -> 0 | W27: =T27-S27 -> 0
A28: 163.047 | G28: =+F28-C28 -> 0 | I28: =F28-E28 -> 0 | N28: =+M28-J28 -> 0 | P28: =M28-L28 -> 0 | Q28: =C28*$B$60+J28*$B$61 -> 0 | S28: =E28*$B$60+L28*$B$61 -> 0 | T28: =F28*$B$60+M28*$B$61 -> 0 | U28: =+T28-Q28 -> 0 | V28: =+T28-R28 -> 0 | W28: =T28-S28 -> 0
A29: 138.414 | B29: 12279.034 | C29: 33.58299 | E29: ='2 блок'!D61 -> 30 | F29: ='2 блок'!E61 -> 25.142857 | G29: =+F29-C29 -> -3.4871429 | I29: =F29-E29 -> -4.8571429 | J29: 32.01117 | L29: ='3 блок'!D84 -> 20 | M29: ='3 блок'!E84 -> 16.857143 | N29: =+M29-J29 -> -10.432857 | P29: =M29-L29 -> -3.1428571 | Q29: =C29*$B$60+J29*$B$61 -> 27.96469 | S29: =E29*$B$60+L29*$B$61 -> 25.035 | T29: =F29*$B$60+M29*$B$61 -> 21.029 | U29: =+T29-Q29 -> -6.93569 | V29: =+T29-R29 -> 21.029 | W29: =T29-S29 -> -4.006
A30: 219.351 | G30: =+F30-C30 -> 0 | I30: =F30-E30 -> 0 | N30: =+M30-J30 -> 0 | P30: =M30-L30 -> 0 | Q30: =C30*$B$60+J30*$B$61 -> 0 | S30: =E30*$B$60+L30*$B$61 -> 0 | T30: =F30*$B$60+M30*$B$61 -> 0 | U30: =+T30-Q30 -> 0 | V30: =+T30-R30 -> 0 | W30: =T30-S30 -> 0
A31: 220.524 | G31: =+F31-C31 -> 0 | I31: =F31-E31 -> 0 | N31: =+M31-J31 -> 0 | P31: =M31-L31 -> 0 | Q31: =C31*$B$60+J31*$B$61 -> 0 | S31: =E31*$B$60+L31*$B$61 -> 0 | T31: =F31*$B$60+M31*$B$61 -> 0 | U31: =+T31-Q31 -> 0 | V31: =+T31-R31 -> 0 | W31: =T31-S31 -> 0
A32: 114.954 | G32: =+F32-C32 -> 0 | I32: =F32-E32 -> 0 | N32: =+M32-J32 -> 0 | P32: =M32-L32 -> 0 | Q32: =C32*$B$60+J32*$B$61 -> 0 | S32: =E32*$B$60+L32*$B$61 -> 0 | T32: =F32*$B$60+M32*$B$61 -> 0 | U32: =+T32-Q32 -> 0 | V32: =+T32-R32 -> 0 | W32: =T32-S32 -> 0
A33: 288.558 | E33: 0 | G33: =+F33-C33 -> 0 | I33: =F33-E33 -> 0 | N33: =+M33-J33 -> 0 | P33: =M33-L33 -> 0 | Q33: =C33*$B$60+J33*$B$61 -> 0 | S33: =E33*$B$60+L33*$B$61 -> 0 | T33: =F33*$B$60+M33*$B$61 -> 0 | U33: =+T33-Q33 -> 0 | V33: =+T33-R33 -> 0 | W33: =T33-S33 -> 0
A34: 145.452 | B34: 15416.739 | G34: =+F34-C34 -> 0 | I34: =F34-E34 -> 0 | N34: =+M34-J34 -> 0 | P34: =M34-L34 -> 0 | Q34: =C34*$B$60+J34*$B$61 -> 0 | S34: =E34*$B$60+L34*$B$61 -> 0 | T34: =F34*$B$60+M34*$B$61 -> 0 | U34: =+T34-Q34 -> 0 | V34: =+T34-R34 -> 0 | W34: =T34-S34 -> 0
A35: 351.9 | B35: ='2 блок'!C72 -> 12162.13 | C35: 7.14357 | E35: ='2 блок'!D67+'2 блок'!D72 -> 9 | F35: ='2 блок'!E72+'2 блок'!E67 -> 8.2244898 | G35: =+F35-C35 -> 2.1344898 | I35: =F35-E35 -> -0.7755102 | J35: 5.79462 | L35: ='3 блок'!D100+'3 блок'!D102 -> 0 | M35: ='3 блок'!E100+'3 блок'!E102 -> 0 | N35: =+M35-J35 -> -4.94 | P35: =M35-L35 -> 0 | Q35: =C35*$B$60+J35*$B$61 -> 5.519025 | S35: =E35*$B$60+L35*$B$61 -> 4.5315 | T35: =F35*$B$60+M35*$B$61 -> 4.1410306 | U35: =+T35-Q35 -> -1.3779944 | V35: =+T35-R35 -> 4.1410306 | W35: =T35-S35 -> -0.39046939
A36: 272.136 | E36: ='2 блок'!D79 -> 0 | G36: =+F36-C36 -> 0 | I36: =F36-E36 -> 0 | N36: =+M36-J36 -> 0 | P36: =M36-L36 -> 0 | Q36: =C36*$B$60+J36*$B$61 -> 0 | S36: =E36*$B$60+L36*$B$61 -> 0 | T36: =F36*$B$60+M36*$B$61 -> 0 | U36: =+T36-Q36 -> 0 | V36: =+T36-R36 -> 0 | W36: =T36-S36 -> 0
A37: 276.828 | B37: 15241.458 | C37: 0.21114 | E37: ='2 блок'!D82 -> 0 | F37: ='2 блок'!E82 -> 0 | G37: =+F37-C37 -> -0.18 | I37: =F37-E37 -> 0 | N37: =+M37-J37 -> 0 | P37: =M37-L37 -> 0 | Q37: =C37*$B$60+J37*$B$61 -> 0.09063 | S37: =E37*$B$60+L37*$B$61 -> 0 | T37: =F37*$B$60+M37*$B$61 -> 0 | U37: =+T37-Q37 -> -0.09063 | V37: =+T37-R37 -> 0 | W37: =T37-S37 -> 0
A38: 300.288 | B38: 14825.101 | C38: 7.56585 | E38: ='2 блок'!D76 -> 0 | F38: ='2 блок'!E76 -> 0 | G38: =+F38-C38 -> -6.45 | I38: =F38-E38 -> 0 | N38: =+M38-J38 -> 0 | P38: =M38-L38 -> 0 | Q38: =C38*$B$60+J38*$B$61 -> 3.247575 | S38: =E38*$B$60+L38*$B$61 -> 0 | T38: =F38*$B$60+M38*$B$61 -> 0 | U38: =+T38-Q38 -> -3.247575 | V38: =+T38-R38 -> 0 | W38: =T38-S38 -> 0
A39: 95.013 | B39: 11756.181 | C39: 17.81787 | E39: ='2 блок'!D84 -> 15 | F39: ='2 блок'!E84 -> 15.918367 | G39: =+F39-C39 -> 0.72836735 | I39: =F39-E39 -> 0.91836735 | J39: 18.07593 | L39: ='3 блок'!D111 -> 10 | M39: ='3 блок'!E111 -> 6.8163265 | N39: =+M39-J39 -> -8.5936735 | P39: =M39-L39 -> -3.1836735 | Q39: =C39*$B$60+J39*$B$61 -> 15.29923 | S39: =E39*$B$60+L39*$B$61 -> 12.5175 | T39: =F39*$B$60+M39*$B$61 -> 11.399204 | U39: =+T39-Q39 -> -3.9000259 | V39: =+T39-R39 -> 11.399204 | W39: =T39-S39 -> -1.1182959
A40: 292.077 | B40: 11023.056 | F40: ='2 блок'!E90 -> 0 | G40: =+F40-C40 -> 0 | I40: =F40-E40 -> 0 | L40: ='3 блок'!D125 -> 0 | M40: ='3 блок'!E125 -> 0 | N40: =+M40-J40 -> 0 | P40: =M40-L40 -> 0 | Q40: =C40*$B$60+J40*$B$61 -> 0 | S40: =E40*$B$60+L40*$B$61 -> 0 | T40: =F40*$B$60+M40*$B$61 -> 0 | U40: =+T40-Q40 -> 0 | V40: =+T40-R40 -> 0 | W40: =T40-S40 -> 0
A41: 117.3 | B41: 11252.659 | C41: 3.81225 | E41: ='2 блок'!D94 -> 5 | F41: ='2 блок'!E94 -> 8.5306122 | G41: =+F41-C41 -> 5.2806122 | I41: =F41-E41 -> 3.5306122 | J41: 3.81225 | L41: ='3 блок'!D128 -> 9 | M41: ='3 блок'!E128 -> 5.6122449 | N41: =+M41-J41 -> 2.3622449 | P41: =M41-L41 -> -3.3877551 | Q41: =C41*$B$60+J41*$B$61 -> 3.25 | S41: =E41*$B$60+L41*$B$61 -> 6.986 | T41: =F41*$B$60+M41*$B$61 -> 7.0816429 | U41: =+T41-Q41 -> 3.8316429 | V41: =+T41-R41 -> 7.0816429 | W41: =T41-S41 -> 0.095642857
A42: 296.769 | B42: 11455.717 | C42: 9.45438 | E42: ='2 блок'!D105 -> 9 | F42: ='2 блок'!E105 -> 8.2244898 | G42: =+F42-C42 -> 0.1644898 | I42: =F42-E42 -> -0.7755102 | J42: 8.87961 | L42: ='3 блок'!D142 -> 10 | M42: ='3 блок'!E142 -> 16.285714 | N42: =+M42-J42 -> 8.7157143 | P42: =M42-L42 -> 6.2857143 | Q42: =C42*$B$60+J42*$B$61 -> 7.816715 | S42: =E42*$B$60+L42*$B$61 -> 9.4965 | T42: =F42*$B$60+M42*$B$61 -> 12.226888 | U42: =+T42-Q42 -> 4.4101728 | V42: =+T42-R42 -> 12.226888 | W42: =T42-S42 -> 2.7303878
...
